<?xml version="1.0" ?>
<!-- =================================================================================== -->
<!-- |    This document was autogenerated by xacro from /home/fhtw_user/catkin_ws/src/butler_2.0/butler_description/urdf/butler/butler.urdf.xacro | -->
<!-- |    EDITING THIS FILE BY HAND IS NOT RECOMMENDED                                 | -->
<!-- =================================================================================== -->
<robot name="butler">
    <!-- path the to the yaml with the arms calibration parameters. -->
    <!-- This file is only for backward compatibility before the "mir_100" to "mir" rename. -->
    <!-- necessary because args cannot be accessed inside ${} expressions -->
    <link name="base_footprint" />
    <joint name="base_joint" type="fixed">
        <parent link="base_footprint" />
        <child link="base_link" />
        <origin rpy="0 0 0" xyz="0 0 0" />
    </joint>
    <link name="base_link">
        <inertial>
            <mass value="77.0" />
            <origin rpy="0 0 0" xyz="-0.012354000000000004 0.0 0.15" />
            <inertia ixx="0.8341663330000001" ixy="0.0" ixz="0.0" iyy="1.8608325890000004" iyz="0.0" izz="2.1816657939999997" />
        </inertial>
        <visual>
            <origin rpy="0 0 0" xyz="0.037646 0 0" />
            <geometry>
                <mesh filename="package://mir_description/meshes/visual/mir_100_base.stl" />
            </geometry>
            <material name="white">
                <color rgba="1 1 1 1" />
            </material>
        </visual>
        <collision>
            <origin rpy="0 0 0" xyz="0.037646 0 0" />
            <geometry>
                <mesh filename="package://mir_description/meshes/collision/mir_100_base.stl" />
            </geometry>
        </collision>
    </link>
    <gazebo reference="base_link">
        <material>Gazebo/White</material>
        <plugin name="gazebo_ros_control">
            <robotNamespace>/</robotNamespace>
        </plugin>
    </gazebo>
    <!-- IMU -->
    <joint name="base_link_to_imu_joint" type="fixed">
        <parent link="base_link" />
        <child link="imu_link" />
        <origin rpy="0 0 0" xyz="0.0 0.0 0.25" />
        <!-- same as real MiR -->
    </joint>
    <link name="imu_link" />
    <gazebo>
        <plugin filename="libhector_gazebo_ros_imu.so" name="imu_plugin">
            <updateRate>50.0</updateRate>
            <bodyName>imu_link</bodyName>
            <frameId>imu_frame</frameId>
            <!-- from real MiR -->
            <topicName>imu_data</topicName>
            <accelDrift>0.0 0.0 0.0</accelDrift>
            <accelGaussianNoise>0.007071067811865475 0.01 0.011401754250991379</accelGaussianNoise>
            <!-- real MiR linear_acceleration_covariance: [5e-05, 0.0, 0.0, 0.0, 0.0001, 0.0, 0.0, 0.0, 0.00013] -->
            <rateDrift>0.0 0.0 0.0</rateDrift>
            <rateGaussianNoise>0.00282842712474619 0.00282842712474619 0.0005477225575051661</rateGaussianNoise>
            <!-- real MiR angular_velocity_covariance: [8e-06, 0.0, 0.0, 0.0, 8e-06, 0.0, 0.0, 0.0, 3e-07] -->
            <yawDrift>0.0</yawDrift>
            <yawGaussianNoise>0.31622776601683794</yawGaussianNoise>
            <!-- real MiR orientation_covariance: [0.1, 0.0, 0.0, 0.0, 0.1, 0.0, 0.0, 0.0, 0.1] -->
        </plugin>
    </gazebo>
    <!-- Create an alias for imu_link. This is necessary because the real MiR's
         TF has imu_link, but the imu_data topic is published in the imu_frame
         frame. -->
    <joint name="imu_link_to_imu_frame_joint" type="fixed">
        <parent link="imu_link" />
        <child link="imu_frame" />
        <origin rpy="0 0 0" xyz="0 0 0" />
    </joint>
    <link name="imu_frame" />
    <!-- Laser scanners -->
    <joint name="base_link_to_front_laser_joint" type="fixed">
        <parent link="base_link" />
        <child link="front_laser_link" />
        <origin rpy="0.0 0.0 0.7853981633974483" xyz="0.42964600000000003 0.2358 0.1914" />
    </joint>
    <link name="front_laser_link">
        <visual>
            <origin rpy="3.141592653589793 0 0" xyz="0.0 0.0 0.0" />
            <geometry>
                <mesh filename="package://mir_description/meshes/visual/sick_lms-100.stl" />
            </geometry>
            <!-- <xacro:insert_block name="material_yellow" /> -->
            <material name="black">
                <color rgba="0.1 0.1 0.1 1" />
            </material>
        </visual>
        <collision>
            <origin rpy="3.141592653589793 0 0" xyz="0.0 0.0 0.0" />
            <geometry>
                <mesh filename="package://mir_description/meshes/visual/sick_lms-100.stl" />
            </geometry>
        </collision>
        <inertial>
            <mass value="1.2" />
            <origin xyz="0 0 0" rpy="0 0 0" />
            <inertia ixx="0.005824997669999999" ixy="0.0" ixz="0.0" iyy="0.00585609765756" iyz="0.0" izz="0.00483609806556" />
        </inertial>
    </link>
    <gazebo reference="front_laser_link">
        <!-- <material value="Gazebo/Yellow" /> -->
        <material value="Gazebo/FlatBlack" />
        <sensor name="front_laser_link" type="ray">
            <pose>0 0 0 0 0 0</pose>
            <visualize>false</visualize>
            <update_rate>12.5</update_rate>
            <ray>
                <scan>
                    <horizontal>
                        <samples>541</samples>
                        <resolution>1</resolution>
                        <!-- has to be 1; actual resolution will be computed from number of samples + min_angle/max_angle -->
                        <min_angle>-2.35619449615</min_angle>
                        <max_angle>2.35619449615</max_angle>
                    </horizontal>
                </scan>
                <range>
                    <min>0.05</min>
                    <max>29.0</max>
                    <resolution>0.01</resolution>
                </range>
                <noise>
                    <type>gaussian</type>
                    <!-- Noise parameters based on published spec for S300 achieving
                 "+-29mm" accuracy at range < 3m (~0.01 of the range) at
                 1 sigma. -->
                    <mean>0.0</mean>
                    <stddev>0.01</stddev>
                </noise>
            </ray>
            <plugin filename="libgazebo_ros_laser.so" name="gazebo_ros_front_laser_link_controller">
                <frameName>front_laser_link</frameName>
                <topicName>f_scan</topicName>
            </plugin>
        </sensor>
    </gazebo>
    <joint name="base_link_to_back_laser_joint" type="fixed">
        <parent link="base_link" />
        <child link="back_laser_link" />
        <origin rpy="0.0 0.0 -2.356194490192345" xyz="-0.354354 -0.2358 0.1914" />
    </joint>
    <link name="back_laser_link">
        <visual>
            <origin rpy="3.141592653589793 0 0" xyz="0.0 0.0 0.0" />
            <geometry>
                <mesh filename="package://mir_description/meshes/visual/sick_lms-100.stl" />
            </geometry>
            <!-- <xacro:insert_block name="material_yellow" /> -->
            <material name="black">
                <color rgba="0.1 0.1 0.1 1" />
            </material>
        </visual>
        <collision>
            <origin rpy="3.141592653589793 0 0" xyz="0.0 0.0 0.0" />
            <geometry>
                <mesh filename="package://mir_description/meshes/visual/sick_lms-100.stl" />
            </geometry>
        </collision>
        <inertial>
            <mass value="1.2" />
            <origin xyz="0 0 0" rpy="0 0 0" />
            <inertia ixx="0.005824997669999999" ixy="0.0" ixz="0.0" iyy="0.00585609765756" iyz="0.0" izz="0.00483609806556" />
        </inertial>
    </link>
    <gazebo reference="back_laser_link">
        <!-- <material value="Gazebo/Yellow" /> -->
        <material value="Gazebo/FlatBlack" />
        <sensor name="back_laser_link" type="ray">
            <pose>0 0 0 0 0 0</pose>
            <visualize>false</visualize>
            <update_rate>12.5</update_rate>
            <ray>
                <scan>
                    <horizontal>
                        <samples>541</samples>
                        <resolution>1</resolution>
                        <!-- has to be 1; actual resolution will be computed from number of samples + min_angle/max_angle -->
                        <min_angle>-2.35619449615</min_angle>
                        <max_angle>2.35619449615</max_angle>
                    </horizontal>
                </scan>
                <range>
                    <min>0.05</min>
                    <max>29.0</max>
                    <resolution>0.01</resolution>
                </range>
                <noise>
                    <type>gaussian</type>
                    <!-- Noise parameters based on published spec for S300 achieving
                 "+-29mm" accuracy at range < 3m (~0.01 of the range) at
                 1 sigma. -->
                    <mean>0.0</mean>
                    <stddev>0.01</stddev>
                </noise>
            </ray>
            <plugin filename="libgazebo_ros_laser.so" name="gazebo_ros_back_laser_link_controller">
                <frameName>back_laser_link</frameName>
                <topicName>b_scan</topicName>
            </plugin>
        </sensor>
    </gazebo>
    <!-- Ultrasound sensors -->
    <joint name="us_1_joint" type="fixed">
        <!-- right ultrasound -->
        <parent link="base_link" />
        <child link="us_1_frame" />
        <origin rpy="0 0 0" xyz="0.45 -0.12 0.16 " />
        <!-- from visually matching to the mesh of the MiR -->
    </joint>
    <link name="us_1_frame" />
    <joint name="us_2_joint" type="fixed">
        <!-- left ultrasound -->
        <parent link="base_link" />
        <child link="us_2_frame" />
        <origin rpy="0 0 0" xyz="0.45 0.12 0.16 " />
        <!-- from visually matching to the mesh of the MiR -->
    </joint>
    <link name="us_2_frame" />
    <joint name="left_wheel_joint" type="continuous">
        <origin rpy="0 0 0" xyz="0.0 0.222604 0.0625" />
        <parent link="base_link" />
        <child link="left_wheel_link" />
        <axis xyz="0 1 0" />
        <limit effort="100" velocity="20.0" />
    </joint>
    <link name="left_wheel_link">
        <inertial>
            <mass value="1.0" />
            <origin rpy="1.5707963267948966 0 0" xyz="0 0 0" />
            <inertia ixx="0.001061895408575" ixy="0.0" ixz="0.0" iyy="0.001061895408575" iyz="0.0" izz="0.001953125" />
        </inertial>
        <visual>
            <origin rpy="1.5707963267948966 0 0" xyz="0 0 0" />
            <geometry>
                <cylinder length="0.032" radius="0.0625" />
            </geometry>
            <material name="black">
                <color rgba="0.1 0.1 0.1 1" />
            </material>
        </visual>
        <collision>
            <origin rpy="1.5707963267948966 0 0" xyz="0 0 0" />
            <geometry>
                <cylinder length="0.032" radius="0.0625" />
            </geometry>
        </collision>
    </link>
    <gazebo reference="left_wheel_link">
        <material>Gazebo/FlatBlack</material>
    </gazebo>
    <joint name="right_wheel_joint" type="continuous">
        <origin rpy="0 0 0" xyz="0.0 -0.222604 0.0625" />
        <parent link="base_link" />
        <child link="right_wheel_link" />
        <axis xyz="0 1 0" />
        <limit effort="100" velocity="20.0" />
    </joint>
    <link name="right_wheel_link">
        <inertial>
            <mass value="1.0" />
            <origin rpy="1.5707963267948966 0 0" xyz="0 0 0" />
            <inertia ixx="0.001061895408575" ixy="0.0" ixz="0.0" iyy="0.001061895408575" iyz="0.0" izz="0.001953125" />
        </inertial>
        <visual>
            <origin rpy="1.5707963267948966 0 0" xyz="0 0 0" />
            <geometry>
                <cylinder length="0.032" radius="0.0625" />
            </geometry>
            <material name="black">
                <color rgba="0.1 0.1 0.1 1" />
            </material>
        </visual>
        <collision>
            <origin rpy="1.5707963267948966 0 0" xyz="0 0 0" />
            <geometry>
                <cylinder length="0.032" radius="0.0625" />
            </geometry>
        </collision>
    </link>
    <gazebo reference="right_wheel_link">
        <material>Gazebo/FlatBlack</material>
    </gazebo>
    <!-- caster hub -->
    <joint name="fl_caster_rotation_joint" type="continuous">
        <origin rpy="0 0 0" xyz="0.34134600000000004 0.203 0.1565" />
        <parent link="base_link" />
        <child link="fl_caster_rotation_link" />
        <axis xyz="0 0 1" />
        <dynamics damping="0.01" friction="0.0" />
    </joint>
    <link name="fl_caster_rotation_link">
        <inertial>
            <!-- <origin xyz="0 0 -0.042500000044" rpy="${0.5 * pi} ${24 * deg_to_rad} ${1.5 * pi}" /> -->
            <origin rpy="0.41887903200000004 0 1.5707963267948966 " xyz="0 0 -0.042500000044" />
            <mass value="0.3097539019" />
            <inertia ixx="0.0005844517978" ixy="0" ixz="0" iyy="0.00052872551237" iyz="0" izz="0.00017923555074" />
        </inertial>
        <visual>
            <origin rpy="0 0 0" xyz="0 0 0" />
            <geometry>
                <mesh filename="package://mir_description/meshes/visual/caster_wheel_base.stl" />
            </geometry>
            <material name="silver">
                <color rgba="0.79 0.82 0.93 1" />
            </material>
        </visual>
        <collision>
            <origin rpy="0 0 0" xyz="0 0 0" />
            <geometry>
                <mesh filename="package://mir_description/meshes/collision/caster_wheel_base.stl" />
            </geometry>
        </collision>
    </link>
    <gazebo reference="fl_caster_rotation_link">
        <material>Gazebo/Grey</material>
    </gazebo>
    <!-- caster wheel -->
    <joint name="fl_caster_wheel_joint" type="continuous">
        <origin rpy="0 0 0" xyz="-0.0382 0 -0.094" />
        <parent link="fl_caster_rotation_link" />
        <child link="fl_caster_wheel_link" />
        <axis xyz="0 1 0" />
    </joint>
    <link name="fl_caster_wheel_link">
        <inertial>
            <mass value="1.0" />
            <origin rpy="1.5707963267948966 0 0" xyz="0 0 0" />
            <inertia ixx="0.001061895408575" ixy="0.0" ixz="0.0" iyy="0.001061895408575" iyz="0.0" izz="0.001953125" />
        </inertial>
        <visual>
            <origin rpy="1.5707963267948966 0 0" xyz="0 0 0" />
            <geometry>
                <cylinder length="0.032" radius="0.0625" />
            </geometry>
            <material name="black">
                <color rgba="0.1 0.1 0.1 1" />
            </material>
        </visual>
        <collision>
            <origin rpy="1.5707963267948966 0 0" xyz="0 0 0" />
            <geometry>
                <cylinder length="0.032" radius="0.0625" />
            </geometry>
        </collision>
    </link>
    <gazebo reference="fl_caster_wheel_link">
        <material>Gazebo/FlatBlack</material>
    </gazebo>
    <!-- caster hub -->
    <joint name="fr_caster_rotation_joint" type="continuous">
        <origin rpy="0 0 0" xyz="0.34134600000000004 -0.203 0.1565" />
        <parent link="base_link" />
        <child link="fr_caster_rotation_link" />
        <axis xyz="0 0 1" />
        <dynamics damping="0.01" friction="0.0" />
    </joint>
    <link name="fr_caster_rotation_link">
        <inertial>
            <!-- <origin xyz="0 0 -0.042500000044" rpy="${0.5 * pi} ${24 * deg_to_rad} ${1.5 * pi}" /> -->
            <origin rpy="0.41887903200000004 0 1.5707963267948966 " xyz="0 0 -0.042500000044" />
            <mass value="0.3097539019" />
            <inertia ixx="0.0005844517978" ixy="0" ixz="0" iyy="0.00052872551237" iyz="0" izz="0.00017923555074" />
        </inertial>
        <visual>
            <origin rpy="0 0 0" xyz="0 0 0" />
            <geometry>
                <mesh filename="package://mir_description/meshes/visual/caster_wheel_base.stl" />
            </geometry>
            <material name="silver">
                <color rgba="0.79 0.82 0.93 1" />
            </material>
        </visual>
        <collision>
            <origin rpy="0 0 0" xyz="0 0 0" />
            <geometry>
                <mesh filename="package://mir_description/meshes/collision/caster_wheel_base.stl" />
            </geometry>
        </collision>
    </link>
    <gazebo reference="fr_caster_rotation_link">
        <material>Gazebo/Grey</material>
    </gazebo>
    <!-- caster wheel -->
    <joint name="fr_caster_wheel_joint" type="continuous">
        <origin rpy="0 0 0" xyz="-0.0382 0 -0.094" />
        <parent link="fr_caster_rotation_link" />
        <child link="fr_caster_wheel_link" />
        <axis xyz="0 1 0" />
    </joint>
    <link name="fr_caster_wheel_link">
        <inertial>
            <mass value="1.0" />
            <origin rpy="1.5707963267948966 0 0" xyz="0 0 0" />
            <inertia ixx="0.001061895408575" ixy="0.0" ixz="0.0" iyy="0.001061895408575" iyz="0.0" izz="0.001953125" />
        </inertial>
        <visual>
            <origin rpy="1.5707963267948966 0 0" xyz="0 0 0" />
            <geometry>
                <cylinder length="0.032" radius="0.0625" />
            </geometry>
            <material name="black">
                <color rgba="0.1 0.1 0.1 1" />
            </material>
        </visual>
        <collision>
            <origin rpy="1.5707963267948966 0 0" xyz="0 0 0" />
            <geometry>
                <cylinder length="0.032" radius="0.0625" />
            </geometry>
        </collision>
    </link>
    <gazebo reference="fr_caster_wheel_link">
        <material>Gazebo/FlatBlack</material>
    </gazebo>
    <!-- caster hub -->
    <joint name="bl_caster_rotation_joint" type="continuous">
        <origin rpy="0 0 0" xyz="-0.270154 0.203 0.1565" />
        <parent link="base_link" />
        <child link="bl_caster_rotation_link" />
        <axis xyz="0 0 1" />
        <dynamics damping="0.01" friction="0.0" />
    </joint>
    <link name="bl_caster_rotation_link">
        <inertial>
            <!-- <origin xyz="0 0 -0.042500000044" rpy="${0.5 * pi} ${24 * deg_to_rad} ${1.5 * pi}" /> -->
            <origin rpy="0.41887903200000004 0 1.5707963267948966 " xyz="0 0 -0.042500000044" />
            <mass value="0.3097539019" />
            <inertia ixx="0.0005844517978" ixy="0" ixz="0" iyy="0.00052872551237" iyz="0" izz="0.00017923555074" />
        </inertial>
        <visual>
            <origin rpy="0 0 0" xyz="0 0 0" />
            <geometry>
                <mesh filename="package://mir_description/meshes/visual/caster_wheel_base.stl" />
            </geometry>
            <material name="silver">
                <color rgba="0.79 0.82 0.93 1" />
            </material>
        </visual>
        <collision>
            <origin rpy="0 0 0" xyz="0 0 0" />
            <geometry>
                <mesh filename="package://mir_description/meshes/collision/caster_wheel_base.stl" />
            </geometry>
        </collision>
    </link>
    <gazebo reference="bl_caster_rotation_link">
        <material>Gazebo/Grey</material>
    </gazebo>
    <!-- caster wheel -->
    <joint name="bl_caster_wheel_joint" type="continuous">
        <origin rpy="0 0 0" xyz="-0.0382 0 -0.094" />
        <parent link="bl_caster_rotation_link" />
        <child link="bl_caster_wheel_link" />
        <axis xyz="0 1 0" />
    </joint>
    <link name="bl_caster_wheel_link">
        <inertial>
            <mass value="1.0" />
            <origin rpy="1.5707963267948966 0 0" xyz="0 0 0" />
            <inertia ixx="0.001061895408575" ixy="0.0" ixz="0.0" iyy="0.001061895408575" iyz="0.0" izz="0.001953125" />
        </inertial>
        <visual>
            <origin rpy="1.5707963267948966 0 0" xyz="0 0 0" />
            <geometry>
                <cylinder length="0.032" radius="0.0625" />
            </geometry>
            <material name="black">
                <color rgba="0.1 0.1 0.1 1" />
            </material>
        </visual>
        <collision>
            <origin rpy="1.5707963267948966 0 0" xyz="0 0 0" />
            <geometry>
                <cylinder length="0.032" radius="0.0625" />
            </geometry>
        </collision>
    </link>
    <gazebo reference="bl_caster_wheel_link">
        <material>Gazebo/FlatBlack</material>
    </gazebo>
    <!-- caster hub -->
    <joint name="br_caster_rotation_joint" type="continuous">
        <origin rpy="0 0 0" xyz="-0.270154 -0.203 0.1565" />
        <parent link="base_link" />
        <child link="br_caster_rotation_link" />
        <axis xyz="0 0 1" />
        <dynamics damping="0.01" friction="0.0" />
    </joint>
    <link name="br_caster_rotation_link">
        <inertial>
            <!-- <origin xyz="0 0 -0.042500000044" rpy="${0.5 * pi} ${24 * deg_to_rad} ${1.5 * pi}" /> -->
            <origin rpy="0.41887903200000004 0 1.5707963267948966 " xyz="0 0 -0.042500000044" />
            <mass value="0.3097539019" />
            <inertia ixx="0.0005844517978" ixy="0" ixz="0" iyy="0.00052872551237" iyz="0" izz="0.00017923555074" />
        </inertial>
        <visual>
            <origin rpy="0 0 0" xyz="0 0 0" />
            <geometry>
                <mesh filename="package://mir_description/meshes/visual/caster_wheel_base.stl" />
            </geometry>
            <material name="silver">
                <color rgba="0.79 0.82 0.93 1" />
            </material>
        </visual>
        <collision>
            <origin rpy="0 0 0" xyz="0 0 0" />
            <geometry>
                <mesh filename="package://mir_description/meshes/collision/caster_wheel_base.stl" />
            </geometry>
        </collision>
    </link>
    <gazebo reference="br_caster_rotation_link">
        <material>Gazebo/Grey</material>
    </gazebo>
    <!-- caster wheel -->
    <joint name="br_caster_wheel_joint" type="continuous">
        <origin rpy="0 0 0" xyz="-0.0382 0 -0.094" />
        <parent link="br_caster_rotation_link" />
        <child link="br_caster_wheel_link" />
        <axis xyz="0 1 0" />
    </joint>
    <link name="br_caster_wheel_link">
        <inertial>
            <mass value="1.0" />
            <origin rpy="1.5707963267948966 0 0" xyz="0 0 0" />
            <inertia ixx="0.001061895408575" ixy="0.0" ixz="0.0" iyy="0.001061895408575" iyz="0.0" izz="0.001953125" />
        </inertial>
        <visual>
            <origin rpy="1.5707963267948966 0 0" xyz="0 0 0" />
            <geometry>
                <cylinder length="0.032" radius="0.0625" />
            </geometry>
            <material name="black">
                <color rgba="0.1 0.1 0.1 1" />
            </material>
        </visual>
        <collision>
            <origin rpy="1.5707963267948966 0 0" xyz="0 0 0" />
            <geometry>
                <cylinder length="0.032" radius="0.0625" />
            </geometry>
        </collision>
    </link>
    <gazebo reference="br_caster_wheel_link">
        <material>Gazebo/FlatBlack</material>
    </gazebo>
    <joint name="base_link_surface_joint" type="fixed">
        <origin rpy="0 0 0" xyz="0.037646 0 0.352" />
        <parent link="base_link" />
        <child link="surface" />
        <axis xyz="0 0 1" />
    </joint>
    <link name="surface" />
    <transmission name="left_wheel_trans">
        <type>transmission_interface/SimpleTransmission</type>
        <joint name="left_wheel_joint">
            <hardwareInterface>hardware_interface/VelocityJointInterface</hardwareInterface>
        </joint>
        <actuator name="left_wheel_motor">
            <hardwareInterface>hardware_interface/VelocityJointInterface</hardwareInterface>
            <mechanicalReduction>1</mechanicalReduction>
        </actuator>
    </transmission>
    <transmission name="right_wheel_trans">
        <type>transmission_interface/SimpleTransmission</type>
        <joint name="right_wheel_joint">
            <hardwareInterface>hardware_interface/VelocityJointInterface</hardwareInterface>
        </joint>
        <actuator name="right_wheel_motor">
            <hardwareInterface>hardware_interface/VelocityJointInterface</hardwareInterface>
            <mechanicalReduction>1</mechanicalReduction>
        </actuator>
    </transmission>
    <gazebo reference="left_wheel_link">
        <mu1 value="200" />
        <mu2 value="200" />
        <kp value="10000000.0" />
        <kd value="1.0" />
        <minDepth>0.01</minDepth>
    </gazebo>
    <gazebo reference="right_wheel_link">
        <mu1 value="200" />
        <mu2 value="200" />
        <kp value="10000000.0" />
        <kd value="1.0" />
        <minDepth>0.01</minDepth>
    </gazebo>
    <gazebo reference="fl_caster_wheel_link">
        <mu1 value="1" />
        <mu2 value="1" />
        <kp value="10000000.0" />
        <kd value="1.0" />
        <minDepth>0.01</minDepth>
    </gazebo>
    <gazebo reference="fr_caster_wheel_link">
        <mu1 value="1" />
        <mu2 value="1" />
        <kp value="10000000.0" />
        <kd value="1.0" />
        <minDepth>0.01</minDepth>
    </gazebo>
    <gazebo reference="bl_caster_wheel_link">
        <mu1 value="1" />
        <mu2 value="1" />
        <kp value="10000000.0" />
        <kd value="1.0" />
        <minDepth>0.01</minDepth>
    </gazebo>
    <gazebo reference="br_caster_wheel_link">
        <mu1 value="1" />
        <mu2 value="1" />
        <kp value="10000000.0" />
        <kd value="1.0" />
        <minDepth>0.01</minDepth>
    </gazebo>
    <gazebo>
        <plugin filename="libgazebo_ros_p3d.so" name="p3d_base_controller">
            <alwaysOn>true</alwaysOn>
            <updateRate>50.0</updateRate>
            <bodyName>base_footprint</bodyName>
            <topicName>base_pose_ground_truth</topicName>
            <gaussianNoise>0.01</gaussianNoise>
            <frameName>map</frameName>
            <xyzOffsets>0 0 0</xyzOffsets>
            <rpyOffsets>0 0 0</rpyOffsets>
        </plugin>
    </gazebo>
    <!-- ############## BODY OF BUTLER ############### -->
    <link name="body">
        <!-- TODO: Needs to have proper values maybe? -->
        <!--
    <inertial>
      <origin xyz="0 0 0.3278534031" rpy="${1.5 * pi} ${0.5 * pi} ${0.5 * pi}" />
      <mass value="3.349376" />
      <inertia
        ixx="0.432077541"
        ixy="0"
        ixz="0"
        iyy="0.369249471"
        iyz="0"
        izz="0.179676981" />
    </inertial>
    -->
        <visual>
            <origin rpy="0 0 0" xyz="0 0 0" />
            <geometry>
                <mesh filename="package://butler_description/meshes/visual/body.obj" scale="0.001 0.001 0.001" />
            </geometry>
        </visual>
        <collision>
            <origin rpy="-1.5707963267948966 0 -1.5707963267948966" xyz="0 0.271 0.270" />
            <geometry>
                <mesh filename="package://butler_description/meshes/collision/body.stl" />
            </geometry>
        </collision>
        <inertial>
            <mass value="0.1" />
            <origin xyz="0 0 0" rpy="0 0 0" />
            <inertia ixx="0.03" iyy="0.03" izz="0.03" ixy="0.0" ixz="0.0" iyz="0.0" />
        </inertial>
    </link>
    <!-- join butler body with MIR100 -->
    <joint name="mir_struct_joint" type="fixed">
        <parent link="surface" />
        <child link="body" />
        <!-- TODO: have those values as parameters -->
        <origin rpy="0.0 0.0 0.0" xyz="0.383 -0.271 0.0" />
    </joint>
    <!-- ############## LOGO COVER ############### -->
    <link name="cover_left">
        <!-- <xacro:box_inertial mass="2.266" x="${cover_thickness}" y="${structure_length}" z="${cover_height}">
      <origin xyz="0 0 0" />
    </xacro:box_inertial> -->
        <visual>
            <origin rpy="0 0 0" xyz="0 0 0" />
            <geometry>
                <mesh filename="package://butler_description/meshes/visual/cover_left_with_logo.dae" />
            </geometry>
        </visual>
        <collision>
            <origin rpy="0 0 0" xyz="0 0 0" />
            <geometry>
                <mesh filename="package://butler_description/meshes/visual/cover_left_with_logo.dae" />
            </geometry>
        </collision>
        <inertial>
            <mass value="0.1" />
            <origin xyz="0 0 0" rpy="0 0 0" />
            <inertia ixx="0.03" iyy="0.03" izz="0.03" ixy="0.0" ixz="0.0" iyz="0.0" />
        </inertial>
    </link>
    <!-- join logo cover with butler body -->
    <joint name="cover_left_joint" type="fixed">
        <origin rpy="0 0 1.5707963267948966" xyz="-0.378 0.5405000000000001 0.27" />
        <parent link="body" />
        <child link="cover_left" />
    </joint>
    <!-- join UR5 with butler body -->
    <joint name="struct_ur5_joint" type="fixed">
        <parent link="body" />
        <child link="ur5_base_link" />
        <origin rpy="0.0 0.0 0.0" xyz="-0.263 0.271 0.540" />
    </joint>
    <!--
    Base UR robot series xacro macro.

    NOTE: this is NOT a URDF. It cannot directly be loaded by consumers
    expecting a flattened '.urdf' file. See the top-level '.xacro' for that
    (but note: that .xacro must still be processed by the xacro command).

    For use in '.launch' files: use one of the 'load_urX.launch' convenience
    launch files.

    This file models the base kinematic chain of a UR robot, which then gets
    parameterised by various configuration files to convert it into a UR3(e),
    UR5(e), UR10(e), UR16e or UR20.

    NOTE: the default kinematic parameters (ie: link lengths, frame locations,
    offets, etc) do not correspond to any particular robot. They are defaults
    only. There WILL be non-zero offsets between the Forward Kinematics results
    in TF (ie: robot_state_publisher) and the values reported by the Teach
    Pendant.

    For accurate (and robot-specific) transforms, the 'kinematics_parameters_file'
    parameter MUST point to a .yaml file containing the appropriate values for
    the targetted robot.

    If using the UniversalRobots/Universal_Robots_ROS_Driver, follow the steps
    described in the readme of that repository to extract the kinematic
    calibration from the controller and generate the required .yaml file.

    Main author of the migration to yaml configs: Ludovic Delval.

    Contributors to previous versions (in no particular order):

     - Felix Messmer
     - Kelsey Hawkins
     - Wim Meeussen
     - Shaun Edwards
     - Nadia Hammoudeh Garcia
     - Dave Hershberger
     - G. vd. Hoorn
     - Philip Long
     - Dave Coleman
     - Miguel Prada
     - Mathias Luedtke
     - Marcel Schnirring
     - Felix von Drigalski
     - Felix Exner
     - Jimmy Da Silva
     - Ajit Krisshna N L
     - Muhammad Asif Rana
  -->
    <!--
    NOTE: the macro defined in this file is NOT part of the public API of this
          package. Users CANNOT rely on this file being available, or stored in
          this location. Nor can they rely on the existence of the macro.
  -->
    <transmission name="ur5_shoulder_pan_trans">
        <type>transmission_interface/SimpleTransmission</type>
        <joint name="ur5_shoulder_pan_joint">
            <hardwareInterface>hardware_interface/PositionJointInterface</hardwareInterface>
        </joint>
        <actuator name="ur5_shoulder_pan_motor">
            <mechanicalReduction>1</mechanicalReduction>
<<<<<<< HEAD
            <hardwareInterface>hardware_interface/PositionJointInterface</hardwareInterface>
=======
            <hardwareInterface>hardware_interface/EffortJointInterface</hardwareInterface>
>>>>>>> 0fff205e22b80033fad84d8c62cb3e19703309a8
        </actuator>
    </transmission>
    <transmission name="ur5_shoulder_lift_trans">
        <type>transmission_interface/SimpleTransmission</type>
        <joint name="ur5_shoulder_lift_joint">
            <hardwareInterface>hardware_interface/PositionJointInterface</hardwareInterface>
        </joint>
        <actuator name="ur5_shoulder_lift_motor">
            <mechanicalReduction>1</mechanicalReduction>
<<<<<<< HEAD
            <hardwareInterface>hardware_interface/PositionJointInterface</hardwareInterface>
=======
            <hardwareInterface>hardware_interface/EffortJointInterface</hardwareInterface>
>>>>>>> 0fff205e22b80033fad84d8c62cb3e19703309a8
        </actuator>
    </transmission>
    <transmission name="ur5_elbow_trans">
        <type>transmission_interface/SimpleTransmission</type>
        <joint name="ur5_elbow_joint">
            <hardwareInterface>hardware_interface/PositionJointInterface</hardwareInterface>
        </joint>
        <actuator name="ur5_elbow_motor">
            <mechanicalReduction>1</mechanicalReduction>
<<<<<<< HEAD
            <hardwareInterface>hardware_interface/PositionJointInterface</hardwareInterface>
=======
            <hardwareInterface>hardware_interface/EffortJointInterface</hardwareInterface>
>>>>>>> 0fff205e22b80033fad84d8c62cb3e19703309a8
        </actuator>
    </transmission>
    <transmission name="ur5_wrist_1_trans">
        <type>transmission_interface/SimpleTransmission</type>
        <joint name="ur5_wrist_1_joint">
            <hardwareInterface>hardware_interface/PositionJointInterface</hardwareInterface>
        </joint>
        <actuator name="ur5_wrist_1_motor">
            <mechanicalReduction>1</mechanicalReduction>
<<<<<<< HEAD
            <hardwareInterface>hardware_interface/PositionJointInterface</hardwareInterface>
=======
            <hardwareInterface>hardware_interface/EffortJointInterface</hardwareInterface>
>>>>>>> 0fff205e22b80033fad84d8c62cb3e19703309a8
        </actuator>
    </transmission>
    <transmission name="ur5_wrist_2_trans">
        <type>transmission_interface/SimpleTransmission</type>
        <joint name="ur5_wrist_2_joint">
            <hardwareInterface>hardware_interface/PositionJointInterface</hardwareInterface>
        </joint>
        <actuator name="ur5_wrist_2_motor">
            <mechanicalReduction>1</mechanicalReduction>
<<<<<<< HEAD
            <hardwareInterface>hardware_interface/PositionJointInterface</hardwareInterface>
=======
            <hardwareInterface>hardware_interface/EffortJointInterface</hardwareInterface>
>>>>>>> 0fff205e22b80033fad84d8c62cb3e19703309a8
        </actuator>
    </transmission>
    <transmission name="ur5_wrist_3_trans">
        <type>transmission_interface/SimpleTransmission</type>
        <joint name="ur5_wrist_3_joint">
            <hardwareInterface>hardware_interface/PositionJointInterface</hardwareInterface>
        </joint>
        <actuator name="ur5_wrist_3_motor">
            <mechanicalReduction>1</mechanicalReduction>
<<<<<<< HEAD
            <hardwareInterface>hardware_interface/PositionJointInterface</hardwareInterface>
=======
            <hardwareInterface>hardware_interface/EffortJointInterface</hardwareInterface>
>>>>>>> 0fff205e22b80033fad84d8c62cb3e19703309a8
        </actuator>
    </transmission>
    <!-- links: main serial chain -->
    <link name="ur5_base_link" />
    <link name="ur5_base_link_inertia">
        <visual>
            <origin rpy="0 0 3.141592653589793" xyz="0 0 0" />
            <geometry>
                <mesh filename="package://ur_description/meshes/ur5/visual/base.dae" />
            </geometry>
            <material name="LightGrey">
                <color rgba="0.7 0.7 0.7 1.0" />
            </material>
        </visual>
        <collision>
            <origin rpy="0 0 3.141592653589793" xyz="0 0 0" />
            <geometry>
                <mesh filename="package://ur_description/meshes/ur5/collision/base.stl" />
            </geometry>
        </collision>
        <inertial>
            <mass value="4.0" />
            <origin rpy="0 0 0" xyz="0 0 0" />
            <inertia ixx="0.00443333156" ixy="0.0" ixz="0.0" iyy="0.00443333156" iyz="0.0" izz="0.0072" />
        </inertial>
    </link>
    <link name="ur5_shoulder_link">
        <visual>
            <origin rpy="0 0 3.141592653589793" xyz="0 0 0" />
            <geometry>
                <mesh filename="package://ur_description/meshes/ur5/visual/shoulder.dae" />
            </geometry>
            <material name="LightGrey">
                <color rgba="0.7 0.7 0.7 1.0" />
            </material>
        </visual>
        <collision>
            <origin rpy="0 0 3.141592653589793" xyz="0 0 0" />
            <geometry>
                <mesh filename="package://ur_description/meshes/ur5/collision/shoulder.stl" />
            </geometry>
        </collision>
        <inertial>
            <mass value="3.7" />
            <origin rpy="0 0 0" xyz="0 0 0" />
            <inertia ixx="0.014972352344389999" ixy="0.0" ixz="0.0" iyy="0.014972352344389999" iyz="0.0" izz="0.01040625" />
        </inertial>
    </link>
    <link name="ur5_upper_arm_link">
        <visual>
            <origin rpy="1.5707963267948966 0 -1.5707963267948966" xyz="0 0 0.13585" />
            <geometry>
                <mesh filename="package://ur_description/meshes/ur5/visual/upperarm.dae" />
            </geometry>
            <material name="LightGrey">
                <color rgba="0.7 0.7 0.7 1.0" />
            </material>
        </visual>
        <collision>
            <origin rpy="1.5707963267948966 0 -1.5707963267948966" xyz="0 0 0.13585" />
            <geometry>
                <mesh filename="package://ur_description/meshes/ur5/collision/upperarm.stl" />
            </geometry>
        </collision>
        <inertial>
            <mass value="8.393" />
            <origin rpy="0 1.5707963267948966 0" xyz="-0.2125 0.0 0.136" />
            <inertia ixx="0.1338857818623325" ixy="0.0" ixz="0.0" iyy="0.1338857818623325" iyz="0.0" izz="0.0151074" />
        </inertial>
    </link>
    <link name="ur5_forearm_link">
        <visual>
            <origin rpy="1.5707963267948966 0 -1.5707963267948966" xyz="0 0 0.0165" />
            <geometry>
                <mesh filename="package://ur_description/meshes/ur5/visual/forearm.dae" />
            </geometry>
            <material name="LightGrey">
                <color rgba="0.7 0.7 0.7 1.0" />
            </material>
        </visual>
        <collision>
            <origin rpy="1.5707963267948966 0 -1.5707963267948966" xyz="0 0 0.0165" />
            <geometry>
                <mesh filename="package://ur_description/meshes/ur5/collision/forearm.stl" />
            </geometry>
        </collision>
        <inertial>
            <mass value="2.275" />
            <origin rpy="0 1.5707963267948966 0" xyz="-0.196125 0.0 0.0165" />
            <inertia ixx="0.03121679102890359" ixy="0.0" ixz="0.0" iyy="0.03121679102890359" iyz="0.0" izz="0.004095" />
        </inertial>
    </link>
    <link name="ur5_wrist_1_link">
        <visual>
            <!-- TODO: Move this to a parameter -->
            <origin rpy="1.5707963267948966 0 0" xyz="0 0 -0.093" />
            <geometry>
                <mesh filename="package://ur_description/meshes/ur5/visual/wrist1.dae" />
            </geometry>
            <material name="LightGrey">
                <color rgba="0.7 0.7 0.7 1.0" />
            </material>
        </visual>
        <collision>
            <origin rpy="1.5707963267948966 0 0" xyz="0 0 -0.093" />
            <geometry>
                <mesh filename="package://ur_description/meshes/ur5/collision/wrist1.stl" />
            </geometry>
        </collision>
        <inertial>
            <mass value="1.219" />
            <origin rpy="0 0 0" xyz="0 0 0" />
            <inertia ixx="0.0020138887777775" ixy="0.0" ixz="0.0" iyy="0.0020138887777775" iyz="0.0" izz="0.0021942" />
        </inertial>
    </link>
    <link name="ur5_wrist_2_link">
        <visual>
            <origin rpy="0 0 0" xyz="0 0 -0.095" />
            <geometry>
                <mesh filename="package://ur_description/meshes/ur5/visual/wrist2.dae" />
            </geometry>
            <material name="LightGrey">
                <color rgba="0.7 0.7 0.7 1.0" />
            </material>
        </visual>
        <collision>
            <origin rpy="0 0 0" xyz="0 0 -0.095" />
            <geometry>
                <mesh filename="package://ur_description/meshes/ur5/collision/wrist2.stl" />
            </geometry>
        </collision>
        <inertial>
            <mass value="1.219" />
            <origin rpy="0 0 0" xyz="0 0 0" />
            <inertia ixx="0.0018310388509175" ixy="0.0" ixz="0.0" iyy="0.0018310388509175" iyz="0.0" izz="0.0021942" />
        </inertial>
    </link>
    <link name="ur5_wrist_3_link">
        <visual>
            <origin rpy="1.5707963267948966 0 0" xyz="0 0 -0.0818" />
            <geometry>
                <mesh filename="package://ur_description/meshes/ur5/visual/wrist3.dae" />
            </geometry>
            <material name="LightGrey">
                <color rgba="0.7 0.7 0.7 1.0" />
            </material>
        </visual>
        <collision>
            <origin rpy="1.5707963267948966 0 0" xyz="0 0 -0.0818" />
            <geometry>
                <mesh filename="package://ur_description/meshes/ur5/collision/wrist3.stl" />
            </geometry>
        </collision>
        <inertial>
            <mass value="0.1879" />
            <origin rpy="0 0 0" xyz="0.0 0.0 -0.01525" />
            <inertia ixx="8.062472608343e-05" ixy="0.0" ixz="0.0" iyy="8.062472608343e-05" iyz="0.0" izz="0.0001321171875" />
        </inertial>
    </link>
    <!-- joints: main serial chain -->
    <joint name="ur5_base_link-base_link_inertia" type="fixed">
        <parent link="ur5_base_link" />
        <child link="ur5_base_link_inertia" />
        <!-- 'base_link' is REP-103 aligned (so X+ forward), while the internal
           frames of the robot/controller have X+ pointing backwards.
           Use the joint between 'base_link' and 'base_link_inertia' (a dummy
           link/frame) to introduce the necessary rotation over Z (of pi rad).
      -->
        <origin rpy="0 0 3.141592653589793" xyz="0 0 0" />
    </joint>
    <joint name="ur5_shoulder_pan_joint" type="revolute">
        <parent link="ur5_base_link_inertia" />
        <child link="ur5_shoulder_link" />
        <origin rpy="0 0 2.81727992575692e-06" xyz="0 0 0.08936214330885116" />
        <axis xyz="0 0 1" />
        <limit effort="150.0" lower="-3.141592653589793" upper="3.141592653589793" velocity="3.141592653589793" />
        <dynamics damping="0" friction="0" />
    </joint>
    <joint name="ur5_shoulder_lift_joint" type="revolute">
        <parent link="ur5_shoulder_link" />
        <child link="ur5_upper_arm_link" />
        <origin rpy="1.569595294389289 0 2.093609007672084e-05" xyz="0.0001821452893181683 0 0" />
        <axis xyz="0 0 1" />
        <limit effort="150.0" lower="-3.141592653589793" upper="0.7400196028455958" velocity="3.141592653589793" />
        <dynamics damping="0" friction="0" />
    </joint>
    <joint name="ur5_elbow_joint" type="revolute">
        <parent link="ur5_upper_arm_link" />
        <child link="ur5_forearm_link" />
        <origin rpy="3.14157060170481 3.139938372903938 3.141584485809974" xyz="-0.4253088254295869 0 0" />
        <axis xyz="0 0 1" />
        <limit effort="150.0" lower="0.0" upper="2.93005874824808" velocity="3.141592653589793" />
        <dynamics damping="0" friction="0" />
    </joint>
    <joint name="ur5_wrist_1_joint" type="revolute">
        <parent link="ur5_forearm_link" />
        <child link="ur5_wrist_1_link" />
        <origin rpy="3.125621974962372 -3.141105686201642 -3.141576781097763" xyz="-0.3924247057368533 0.001764421912694606 0.1104694383148228" />
        <axis xyz="0 0 1" />
        <limit effort="28.0" lower="-3.141592653589793" upper="0.0" velocity="3.141592653589793" />
        <dynamics damping="0" friction="0" />
    </joint>
    <joint name="ur5_wrist_2_joint" type="revolute">
        <parent link="ur5_wrist_1_link" />
        <child link="ur5_wrist_2_link" />
        <origin rpy="1.570132742697001 0 -5.772759383183389e-05" xyz="1.089910267432447e-05 -0.09481018393202882 6.291453961056355e-05" />
        <axis xyz="0 0 1" />
        <limit effort="28.0" lower="-3.141592653589793" upper="3.141592653589793" velocity="3.141592653589793" />
        <dynamics damping="0" friction="0" />
    </joint>
    <joint name="ur5_wrist_3_joint" type="revolute">
        <parent link="ur5_wrist_2_link" />
        <child link="ur5_wrist_3_link" />
        <origin rpy="1.571518388811858 3.141592653589793 -3.14153022169784" xyz="2.469054499528621e-05 0.08249607896625931 5.956729552210166e-05" />
        <axis xyz="0 0 1" />
        <limit effort="28.0" lower="0.5235987755982988" upper="4.799655442984406" velocity="3.141592653589793" />
        <dynamics damping="0" friction="0" />
    </joint>
    <!-- ROS-Industrial 'base' frame: base_link to UR 'Base' Coordinates transform -->
    <link name="ur5_base" />
    <joint name="ur5_base_link-base_fixed_joint" type="fixed">
        <!-- Note the rotation over Z of pi radians: as base_link is REP-103
           aligned (ie: has X+ forward, Y+ left and Z+ up), this is needed
           to correctly align 'base' with the 'Base' coordinate system of
           the UR controller.
      -->
        <origin rpy="0 0 3.141592653589793" xyz="0 0 0" />
        <parent link="ur5_base_link" />
        <child link="ur5_base" />
    </joint>
    <!-- ROS-Industrial 'flange' frame: attachment point for EEF models -->
    <link name="ur5_flange" />
    <joint name="ur5_wrist_3-flange" type="fixed">
        <parent link="ur5_wrist_3_link" />
        <child link="ur5_flange" />
        <origin rpy="0 -1.5707963267948966 -1.5707963267948966" xyz="0 0 0" />
    </joint>
    <!-- ROS-Industrial 'tool0' frame: all-zeros tool frame -->
    <link name="ur5_tool0" />
    <joint name="ur5_flange-tool0" type="fixed">
        <!-- default toolframe: X+ left, Y+ up, Z+ front -->
        <origin rpy="1.5707963267948966 0 1.5707963267948966" xyz="0 0 0" />
        <parent link="ur5_flange" />
        <child link="ur5_tool0" />
    </joint>
    <!-- Fixed Joint for Gripper to connect to tool0-->
    <!-- <joint name="${prefix}ur5_2f85_joint" type="fixed"> -->
    <!-- <origin xyz="0 0 0" rpy="0 0 0"/> -->
    <!-- <parent link="${prefix}ur5_tool0"/> -->
    <!-- <child link="${prefix}gripper_robotiq_arg2f_base_link"/> -->
    <!-- </joint> -->
    <!-- <xacro:robotiq_arg2f_85 prefix="${prefix}gripper_"/> -->
    <joint name="gripper_robotiq_85_base_joint" type="fixed">
        <parent link="ur5_tool0" />
        <child link="gripper_robotiq_85_base_link" />
        <origin rpy="0.0 -1.5707963267948966 1.5707963267948966" xyz="0 0 0" />
    </joint>
    <link name="gripper_robotiq_85_base_link">
        <visual>
            <geometry>
                <mesh filename="package://robotiq_description/meshes/visual/robotiq_85_base_link.dae" />
            </geometry>
        </visual>
        <collision>
            <geometry>
                <mesh filename="package://robotiq_description/meshes/collision/robotiq_85_base_link.stl" />
            </geometry>
        </collision>
        <inertial>
            <mass value="0.636951" />
            <origin xyz="0.0 0.0 0.0" rpy="0 0 0" />
            <inertia ixx="0.000380" ixy="0.000000" ixz="0.000000" iyx="0.000000" iyy="0.001110" iyz="0.000000" izx="0.000000" izy="0.000000" izz="0.001171" />
        </inertial>
    </link>
    <joint name="gripper_robotiq_85_left_knuckle_joint" type="revolute">
        <parent link="gripper_robotiq_85_base_link" />
        <child link="gripper_robotiq_85_left_knuckle_link" />
        <axis xyz="0 0 1" />
        <origin rpy="3.141592653589793 0.0 0.0" xyz="0.05490451627 0.03060114443 0.0" />
        <limit effort="1000" lower="0.0" upper="0.80285" velocity="0.5" />
    </joint>
    <joint name="gripper_robotiq_85_right_knuckle_joint" type="continuous">
        <parent link="gripper_robotiq_85_base_link" />
        <child link="gripper_robotiq_85_right_knuckle_link" />
        <axis xyz="0 0 1" />
        <origin rpy="0.0 0.0 0.0" xyz="0.05490451627 -0.03060114443 0.0" />
        <limit effort="1000" lower="-3.14" upper="3.14" velocity="100.0" />
        <mimic joint="gripper_robotiq_85_left_knuckle_joint" />
    </joint>
    <link name="gripper_robotiq_85_left_knuckle_link">
        <visual>
            <geometry>
                <mesh filename="package://robotiq_description/meshes/visual/robotiq_85_knuckle_link.dae" />
            </geometry>
        </visual>
        <collision>
            <geometry>
                <mesh filename="package://robotiq_description/meshes/collision/robotiq_85_knuckle_link.stl" />
            </geometry>
        </collision>
        <inertial>
            <mass value="0.018491" />
            <origin xyz="0.0 0.0 0.0" rpy="0 0 0" />
            <inertia ixx="0.000009" ixy="-0.000001" ixz="0.000000" iyx="-0.000001" iyy="0.000001" iyz="0.000000" izx="0.000000" izy="0.000000" izz="0.000010" />
        </inertial>
    </link>
    <link name="gripper_robotiq_85_right_knuckle_link">
        <visual>
            <geometry>
                <mesh filename="package://robotiq_description/meshes/visual/robotiq_85_knuckle_link.dae" />
            </geometry>
        </visual>
        <collision>
            <geometry>
                <mesh filename="package://robotiq_description/meshes/collision/robotiq_85_knuckle_link.stl" />
            </geometry>
        </collision>
        <inertial>
            <mass value="0.018491" />
            <origin xyz="0.0 0.0 0.0" rpy="0 0 0" />
            <inertia ixx="0.000009" ixy="-0.000001" ixz="0.000000" iyx="-0.000001" iyy="0.000001" iyz="0.000000" izx="0.000000" izy="0.000000" izz="0.000010" />
        </inertial>
    </link>
    <joint name="gripper_robotiq_85_left_finger_joint" type="fixed">
        <parent link="gripper_robotiq_85_left_knuckle_link" />
        <child link="gripper_robotiq_85_left_finger_link" />
        <origin rpy="0 0 0" xyz="-0.00408552455 -0.03148604435 0.0" />
    </joint>
    <joint name="gripper_robotiq_85_right_finger_joint" type="fixed">
        <parent link="gripper_robotiq_85_right_knuckle_link" />
        <child link="gripper_robotiq_85_right_finger_link" />
        <origin rpy="0 0 0" xyz="-0.00408552455 -0.03148604435 0.0" />
    </joint>
    <link name="gripper_robotiq_85_left_finger_link">
        <visual>
            <geometry>
                <mesh filename="package://robotiq_description/meshes/visual/robotiq_85_finger_link.dae" />
            </geometry>
        </visual>
        <collision>
            <geometry>
                <mesh filename="package://robotiq_description/meshes/collision/robotiq_85_finger_link.stl" />
            </geometry>
        </collision>
        <inertial>
            <mass value="0.027309" />
            <origin xyz="0.0 0.0 0.0" rpy="0 0 0" />
            <inertia ixx="0.000003" ixy="-0.000002" ixz="0.000000" iyx="-0.000002" iyy="0.000021" iyz="0.000000" izx="0.000000" izy="0.000000" izz="0.000020" />
        </inertial>
    </link>
    <link name="gripper_robotiq_85_right_finger_link">
        <visual>
            <geometry>
                <mesh filename="package://robotiq_description/meshes/visual/robotiq_85_finger_link.dae" />
            </geometry>
        </visual>
        <collision>
            <geometry>
                <mesh filename="package://robotiq_description/meshes/collision/robotiq_85_finger_link.stl" />
            </geometry>
        </collision>
        <inertial>
            <mass value="0.027309" />
            <origin xyz="0.0 0.0 0.0" rpy="0 0 0" />
            <inertia ixx="0.000003" ixy="-0.000002" ixz="0.000000" iyx="-0.000002" iyy="0.000021" iyz="0.000000" izx="0.000000" izy="0.000000" izz="0.000020" />
        </inertial>
    </link>
    <joint name="gripper_robotiq_85_left_inner_knuckle_joint" type="continuous">
        <parent link="gripper_robotiq_85_base_link" />
        <child link="gripper_robotiq_85_left_inner_knuckle_link" />
        <axis xyz="0 0 1" />
        <origin rpy="3.141592653589793 0.0 0.0" xyz="0.06142 0.0127 0" />
        <limit effort="0.1" lower="-3.14" upper="3.14" velocity="100.0" />
        <mimic joint="gripper_robotiq_85_left_knuckle_joint" offset="0" />
    </joint>
    <joint name="gripper_robotiq_85_right_inner_knuckle_joint" type="continuous">
        <parent link="gripper_robotiq_85_base_link" />
        <child link="gripper_robotiq_85_right_inner_knuckle_link" />
        <axis xyz="0 0 1" />
        <origin rpy="0 0 0" xyz="0.06142 -0.0127 0" />
        <limit effort="0.1" lower="-3.14" upper="3.14" velocity="100.0" />
        <mimic joint="gripper_robotiq_85_left_knuckle_joint" offset="0" />
    </joint>
    <link name="gripper_robotiq_85_left_inner_knuckle_link">
        <visual>
            <geometry>
                <mesh filename="package://robotiq_description/meshes/visual/robotiq_85_inner_knuckle_link.dae" />
            </geometry>
        </visual>
        <collision>
            <geometry>
                <mesh filename="package://robotiq_description/meshes/collision/robotiq_85_inner_knuckle_link.stl" />
            </geometry>
        </collision>
        <inertial>
            <mass value="0.029951" />
            <origin xyz="0.0 0.0 0.0" rpy="0 0 0" />
            <inertia ixx="0.000039" ixy="0.000000" ixz="0.000000" iyx="0.000000" iyy="0.000005" iyz="0.000000" izx="0.000000" izy="0.000000" izz="0.000035" />
        </inertial>
    </link>
    <link name="gripper_robotiq_85_right_inner_knuckle_link">
        <visual>
            <geometry>
                <mesh filename="package://robotiq_description/meshes/visual/robotiq_85_inner_knuckle_link.dae" />
            </geometry>
        </visual>
        <collision>
            <geometry>
                <mesh filename="package://robotiq_description/meshes/collision/robotiq_85_inner_knuckle_link.stl" />
            </geometry>
        </collision>
        <inertial>
            <mass value="0.029951" />
            <origin xyz="0.0 0.0 0.0" rpy="0 0 0" />
            <inertia ixx="0.000039" ixy="0.000000" ixz="0.000000" iyx="0.000000" iyy="0.000005" iyz="0.000000" izx="0.000000" izy="0.000000" izz="0.000035" />
        </inertial>
    </link>
    <joint name="gripper_robotiq_85_left_finger_tip_joint" type="continuous">
        <parent link="gripper_robotiq_85_left_inner_knuckle_link" />
        <child link="gripper_robotiq_85_left_finger_tip_link" />
        <axis xyz="0 0 1" />
        <origin rpy="0.0 0.0 0.0" xyz="0.04303959807 -0.03759940821 0.0" />
        <limit effort="0.1" lower="-3.14" upper="3.14" velocity="100.0" />
        <mimic joint="gripper_robotiq_85_left_knuckle_joint" multiplier="-1" />
    </joint>
    <joint name="gripper_robotiq_85_right_finger_tip_joint" type="continuous">
        <parent link="gripper_robotiq_85_right_inner_knuckle_link" />
        <child link="gripper_robotiq_85_right_finger_tip_link" />
        <axis xyz="0 0 1" />
        <origin rpy="0.0 0.0 0.0" xyz="0.04303959807 -0.03759940821  0.0" />
        <limit effort="0.1" lower="-3.14" upper="3.14" velocity="100.0" />
        <mimic joint="gripper_robotiq_85_left_knuckle_joint" multiplier="-1" />
    </joint>
    <link name="gripper_robotiq_85_left_finger_tip_link">
        <visual>
            <geometry>
                <mesh filename="package://robotiq_description/meshes/visual/robotiq_85_finger_tip_link.dae" />
            </geometry>
        </visual>
        <collision>
            <geometry>
                <mesh filename="package://robotiq_description/meshes/collision/robotiq_85_finger_tip_link.stl" />
            </geometry>
        </collision>
        <inertial>
            <mass value="0.019555" />
            <origin xyz="0.0 0.0 0.0" rpy="0 0 0" />
            <inertia ixx="0.000002" ixy="0.000000" ixz="0.000000" iyx="0.000000" iyy="0.000005" iyz="0.000000" izx="0.000000" izy="0.000000" izz="0.000006" />
        </inertial>
    </link>
    <link name="gripper_robotiq_85_right_finger_tip_link">
        <visual>
            <geometry>
                <mesh filename="package://robotiq_description/meshes/visual/robotiq_85_finger_tip_link.dae" />
            </geometry>
        </visual>
        <collision>
            <geometry>
                <mesh filename="package://robotiq_description/meshes/collision/robotiq_85_finger_tip_link.stl" />
            </geometry>
        </collision>
        <inertial>
            <mass value="0.019555" />
            <origin xyz="0.0 0.0 0.0" rpy="0 0 0" />
            <inertia ixx="0.000002" ixy="0.000000" ixz="0.000000" iyx="0.000000" iyy="0.000005" iyz="0.000000" izx="0.000000" izy="0.000000" izz="0.000006" />
        </inertial>
    </link>
    <!-- Improve grasping physics -->
    <gazebo reference="gripper_robotiq_85_left_finger_tip_link">
        <kp>1000000.0</kp>
        <kd>1.0</kd>
        <mu1>1.0</mu1>
        <mu2>1.0</mu2>
        <minDepth>0.001</minDepth>
    </gazebo>
    <gazebo reference="gripper_robotiq_85_right_finger_tip_link">
        <kp>1000000.0</kp>
        <kd>1.0</kd>
        <mu1>1.0</mu1>
        <mu2>1.0</mu2>
        <minDepth>0.001</minDepth>
    </gazebo>
    <transmission name="gripper_robotiq_85_left_knuckle_trans">
        <type>transmission_interface/SimpleTransmission</type>
        <joint name="gripper_robotiq_85_left_knuckle_joint">
            <hardwareInterface>hardware_interface/PositionJointInterface</hardwareInterface>
        </joint>
        <actuator name="gripper_robotiq_85_left_knuckle_motor">
            <mechanicalReduction>1</mechanicalReduction>
            <hardwareInterface>hardware_interface/PositionJointInterface</hardwareInterface>
        </actuator>
    </transmission>
    <!-- Mimic joints -->
    <gazebo>
        <plugin filename="libgazebo_mimic_joint_plugin.so" name="gripper_mimic_robotiq_85_1">
            <joint>gripper_robotiq_85_left_knuckle_joint</joint>
            <mimicJoint>gripper_robotiq_85_right_knuckle_joint</mimicJoint>
        </plugin>
        <plugin filename="libgazebo_mimic_joint_plugin.so" name="gripper_mimic_robotiq_85_2">
            <joint>gripper_robotiq_85_left_knuckle_joint</joint>
            <mimicJoint>gripper_robotiq_85_left_inner_knuckle_joint</mimicJoint>
        </plugin>
        <plugin filename="libgazebo_mimic_joint_plugin.so" name="gripper_mimic_robotiq_85_3">
            <joint>gripper_robotiq_85_left_knuckle_joint</joint>
            <mimicJoint>gripper_robotiq_85_right_inner_knuckle_joint</mimicJoint>
        </plugin>
        <plugin filename="libgazebo_mimic_joint_plugin.so" name="gripper_mimic_robotiq_85_4">
            <joint>gripper_robotiq_85_left_knuckle_joint</joint>
            <mimicJoint>gripper_robotiq_85_left_finger_tip_joint</mimicJoint>
            <multiplier>-1.0</multiplier>
            <offset>0.0</offset>
        </plugin>
        <plugin filename="libgazebo_mimic_joint_plugin.so" name="gripper_mimic_robotiq_85_5">
            <joint>gripper_robotiq_85_left_knuckle_joint</joint>
            <mimicJoint>gripper_robotiq_85_right_finger_tip_joint</mimicJoint>
            <multiplier>-1.0</multiplier>
            <offset>0.0</offset>
        </plugin>
    </gazebo>
<<<<<<< HEAD
    <!-- ############### REALSENSE D435 ################ -->
    <!-- <xacro:include filename="$(find realsense2_description)/urdf/_d435.urdf.xacro" />
  <xacro:sensor_d435 name="camera" parent="${prefix}ur5_tool0">
    <origin xyz="0.0 0.1 0.0" rpy="1.5708 1.5708 0"/>
  </xacro:sensor_d435> -->
=======
>>>>>>> 0fff205e22b80033fad84d8c62cb3e19703309a8
    <gazebo>
        <plugin filename="libgazebo_ros_control.so" name="gazebo_ros_control">
            <controlPeriod>0.001</controlPeriod>
            <legacyModeNS>false</legacyModeNS>
        </plugin>
    </gazebo>
    <!-- MiR100 mobile base -->
    <!-- UR5 arm -->
    <!-- TODO -->
    <!-- force torque sensor-->
    <!-- TODO -->
    <gazebo>
        <plugin filename="libroboticsgroup_upatras_gazebo_mimic_joint_plugin.so" name="gripper_right_outer_knucklemimic_joint_plugin">
            <joint>gripper_finger_joint</joint>
            <mimicJoint>gripper_right_outer_knuckle_joint</mimicJoint>
            <!-- if set to true, PID parameters from "/gazebo_ros_control/pid_gains/${mimic_joint}" are loaded -->
            <hasPID />
            <multiplier>-1.0</multiplier>
            <offset>0</offset>
            <sensitiveness>0.0</sensitiveness>
            <!-- if absolute difference between setpoint and process value is below this threshold, do nothing; 0.0 = disable [rad] -->
            <maxEffort>10.0</maxEffort>
        </plugin>
    </gazebo>
    <transmission name="trans_fl_caster_rotation_joint">
        <type>transmission_interface/SimpleTransmission</type>
        <joint name="fl_caster_rotation_joint">
            <hardwareInterface>hardware_interface/EffortJointInterface</hardwareInterface>
        </joint>
        <actuator name="fl_caster_rotation_joint_motor">
            <hardwareInterface>hardware_interface/EffortJointInterface</hardwareInterface>
            <mechanicalReduction>1</mechanicalReduction>
        </actuator>
    </transmission>
    <transmission name="trans_fl_caster_wheel_joint">
        <type>transmission_interface/SimpleTransmission</type>
        <joint name="fl_caster_wheel_joint">
            <hardwareInterface>hardware_interface/EffortJointInterface</hardwareInterface>
        </joint>
        <actuator name="fl_caster_wheel_joint_motor">
            <hardwareInterface>hardware_interface/EffortJointInterface</hardwareInterface>
            <mechanicalReduction>1</mechanicalReduction>
        </actuator>
    </transmission>
    <transmission name="trans_fr_caster_rotation_joint">
        <type>transmission_interface/SimpleTransmission</type>
        <joint name="fr_caster_rotation_joint">
            <hardwareInterface>hardware_interface/EffortJointInterface</hardwareInterface>
        </joint>
        <actuator name="fr_caster_rotation_joint_motor">
            <hardwareInterface>hardware_interface/EffortJointInterface</hardwareInterface>
            <mechanicalReduction>1</mechanicalReduction>
        </actuator>
    </transmission>
    <transmission name="trans_fr_caster_wheel_joint">
        <type>transmission_interface/SimpleTransmission</type>
        <joint name="fr_caster_wheel_joint">
            <hardwareInterface>hardware_interface/EffortJointInterface</hardwareInterface>
        </joint>
        <actuator name="fr_caster_wheel_joint_motor">
            <hardwareInterface>hardware_interface/EffortJointInterface</hardwareInterface>
            <mechanicalReduction>1</mechanicalReduction>
        </actuator>
    </transmission>
    <transmission name="trans_bl_caster_rotation_joint">
        <type>transmission_interface/SimpleTransmission</type>
        <joint name="bl_caster_rotation_joint">
            <hardwareInterface>hardware_interface/EffortJointInterface</hardwareInterface>
        </joint>
        <actuator name="bl_caster_rotation_joint_motor">
            <hardwareInterface>hardware_interface/EffortJointInterface</hardwareInterface>
            <mechanicalReduction>1</mechanicalReduction>
        </actuator>
    </transmission>
    <transmission name="trans_bl_caster_wheel_joint">
        <type>transmission_interface/SimpleTransmission</type>
        <joint name="bl_caster_wheel_joint">
            <hardwareInterface>hardware_interface/EffortJointInterface</hardwareInterface>
        </joint>
        <actuator name="bl_caster_wheel_joint_motor">
            <hardwareInterface>hardware_interface/EffortJointInterface</hardwareInterface>
            <mechanicalReduction>1</mechanicalReduction>
        </actuator>
    </transmission>
    <transmission name="trans_br_caster_rotation_joint">
        <type>transmission_interface/SimpleTransmission</type>
        <joint name="br_caster_rotation_joint">
            <hardwareInterface>hardware_interface/EffortJointInterface</hardwareInterface>
        </joint>
        <actuator name="br_caster_rotation_joint_motor">
            <hardwareInterface>hardware_interface/EffortJointInterface</hardwareInterface>
            <mechanicalReduction>1</mechanicalReduction>
        </actuator>
    </transmission>
    <transmission name="trans_br_caster_wheel_joint">
        <type>transmission_interface/SimpleTransmission</type>
        <joint name="br_caster_wheel_joint">
            <hardwareInterface>hardware_interface/EffortJointInterface</hardwareInterface>
        </joint>
        <actuator name="br_caster_wheel_joint_motor">
            <hardwareInterface>hardware_interface/EffortJointInterface</hardwareInterface>
            <mechanicalReduction>1</mechanicalReduction>
        </actuator>
    </transmission>
    <transmission name="trans_gripper_robotiq_85_right_knuckle_joint">
        <type>transmission_interface/SimpleTransmission</type>
        <joint name="gripper_robotiq_85_right_knuckle_joint">
            <hardwareInterface>hardware_interface/EffortJointInterface</hardwareInterface>
        </joint>
        <actuator name="gripper_robotiq_85_right_knuckle_joint_motor">
            <hardwareInterface>hardware_interface/EffortJointInterface</hardwareInterface>
            <mechanicalReduction>1</mechanicalReduction>
        </actuator>
    </transmission>
    <transmission name="trans_gripper_robotiq_85_left_inner_knuckle_joint">
        <type>transmission_interface/SimpleTransmission</type>
        <joint name="gripper_robotiq_85_left_inner_knuckle_joint">
            <hardwareInterface>hardware_interface/EffortJointInterface</hardwareInterface>
        </joint>
        <actuator name="gripper_robotiq_85_left_inner_knuckle_joint_motor">
            <hardwareInterface>hardware_interface/EffortJointInterface</hardwareInterface>
            <mechanicalReduction>1</mechanicalReduction>
        </actuator>
    </transmission>
    <transmission name="trans_gripper_robotiq_85_right_inner_knuckle_joint">
        <type>transmission_interface/SimpleTransmission</type>
        <joint name="gripper_robotiq_85_right_inner_knuckle_joint">
            <hardwareInterface>hardware_interface/EffortJointInterface</hardwareInterface>
        </joint>
        <actuator name="gripper_robotiq_85_right_inner_knuckle_joint_motor">
            <hardwareInterface>hardware_interface/EffortJointInterface</hardwareInterface>
            <mechanicalReduction>1</mechanicalReduction>
        </actuator>
    </transmission>
    <transmission name="trans_gripper_robotiq_85_left_finger_tip_joint">
        <type>transmission_interface/SimpleTransmission</type>
        <joint name="gripper_robotiq_85_left_finger_tip_joint">
            <hardwareInterface>hardware_interface/EffortJointInterface</hardwareInterface>
        </joint>
        <actuator name="gripper_robotiq_85_left_finger_tip_joint_motor">
            <hardwareInterface>hardware_interface/EffortJointInterface</hardwareInterface>
            <mechanicalReduction>1</mechanicalReduction>
        </actuator>
    </transmission>
    <transmission name="trans_gripper_robotiq_85_right_finger_tip_joint">
        <type>transmission_interface/SimpleTransmission</type>
        <joint name="gripper_robotiq_85_right_finger_tip_joint">
            <hardwareInterface>hardware_interface/EffortJointInterface</hardwareInterface>
        </joint>
        <actuator name="gripper_robotiq_85_right_finger_tip_joint_motor">
            <hardwareInterface>hardware_interface/EffortJointInterface</hardwareInterface>
            <mechanicalReduction>1</mechanicalReduction>
        </actuator>
    </transmission>
</robot>

